<?xml version="1.0" encoding="UTF-8"?>
<!-- Generated by org.testng.reporters.JUnitReportReporter -->
<testsuite hostname="Phaedros" name="net.groot.data.InvocationCountTest" tests="41" failures="10" timestamp="23 Feb 2020 18:24:39 GMT" time="10.259" errors="0">
  <testcase name="invokeProvider" time="0.006" classname="net.groot.data.InvocationCountTest"/>
  <testcase name="math" time="0.012" classname="net.groot.data.InvocationCountTest">
    <failure type="org.testng.TestException" message="
Expected exception java.lang.NumberFormatException but got org.testng.TestException: 
Method InvocationCountTest.math()[pri:0, instance:net.groot.data.InvocationCountTest@3701eaf6] should have thrown an exception of class java.lang.NumberFormatException">
      <![CDATA[org.testng.TestException: 
Expected exception java.lang.NumberFormatException but got org.testng.TestException: 
Method InvocationCountTest.math()[pri:0, instance:net.groot.data.InvocationCountTest@3701eaf6] should have thrown an exception of class java.lang.NumberFormatException
	at org.testng.internal.Invoker.handleInvocationResults(Invoker.java:1497)
	at org.testng.internal.Invoker.invokeTestMethods(Invoker.java:1245)
	at org.testng.internal.TestMethodWorker.invokeTestMethods(TestMethodWorker.java:127)
	at org.testng.internal.TestMethodWorker.run(TestMethodWorker.java:111)
	at org.testng.TestRunner.privateRun(TestRunner.java:767)
	at org.testng.TestRunner.run(TestRunner.java:617)
	at org.testng.SuiteRunner.runTest(SuiteRunner.java:334)
	at org.testng.SuiteRunner.runSequentially(SuiteRunner.java:329)
	at org.testng.SuiteRunner.privateRun(SuiteRunner.java:291)
	at org.testng.SuiteRunner.run(SuiteRunner.java:240)
	at org.testng.SuiteRunnerWorker.runSuite(SuiteRunnerWorker.java:52)
	at org.testng.SuiteRunnerWorker.run(SuiteRunnerWorker.java:86)
	at org.testng.TestNG.runSuitesSequentially(TestNG.java:1198)
	at org.testng.TestNG.runSuitesLocally(TestNG.java:1123)
	at org.testng.TestNG.run(TestNG.java:1031)
	at org.testng.remote.AbstractRemoteTestNG.run(AbstractRemoteTestNG.java:115)
	at org.testng.remote.RemoteTestNG.initAndRun(RemoteTestNG.java:251)
	at org.testng.remote.RemoteTestNG.main(RemoteTestNG.java:77)
Caused by: org.testng.TestException: 
Method InvocationCountTest.math()[pri:0, instance:net.groot.data.InvocationCountTest@3701eaf6] should have thrown an exception of class java.lang.NumberFormatException
	at org.testng.internal.Invoker.handleInvocationResults(Invoker.java:1512)
	at org.testng.internal.Invoker.invokeMethod(Invoker.java:754)
	at org.testng.internal.Invoker.invokeTestMethod(Invoker.java:901)
	at org.testng.internal.Invoker.invokeTestMethods(Invoker.java:1231)
	... 16 more
]]>
    </failure>
  </testcase> <!-- math -->
  <testcase name="invokeProvider" time="0.001" classname="net.groot.data.InvocationCountTest"/>
  <testcase name="mathError" time="0.001" classname="net.groot.data.InvocationCountTest"/>
  <testcase name="mathError" time="0.001" classname="net.groot.data.InvocationCountTest"/>
  <testcase name="invokeProvider" time="0.001" classname="net.groot.data.InvocationCountTest"/>
  <testcase name="invokeProvider" time="0.004" classname="net.groot.data.InvocationCountTest"/>
  <testcase name="mathError" time="0.002" classname="net.groot.data.InvocationCountTest"/>
  <testcase name="webParameterTest" time="10.129" classname="net.groot.data.InvocationCountTest"/>
  <testcase name="invokeProvider" time="0.002" classname="net.groot.data.InvocationCountTest"/>
  <testcase name="invokeProvider" time="0.005" classname="net.groot.data.InvocationCountTest"/>
  <testcase name="math" time="0.002" classname="net.groot.data.InvocationCountTest">
    <failure type="org.testng.TestException" message="
Expected exception java.lang.NumberFormatException but got org.testng.TestException: 
Method InvocationCountTest.math()[pri:0, instance:net.groot.data.InvocationCountTest@3701eaf6] should have thrown an exception of class java.lang.NumberFormatException">
      <![CDATA[org.testng.TestException: 
Expected exception java.lang.NumberFormatException but got org.testng.TestException: 
Method InvocationCountTest.math()[pri:0, instance:net.groot.data.InvocationCountTest@3701eaf6] should have thrown an exception of class java.lang.NumberFormatException
	at org.testng.internal.Invoker.handleInvocationResults(Invoker.java:1497)
	at org.testng.internal.Invoker.invokeTestMethods(Invoker.java:1245)
	at org.testng.internal.TestMethodWorker.invokeTestMethods(TestMethodWorker.java:127)
	at org.testng.internal.TestMethodWorker.run(TestMethodWorker.java:111)
	at org.testng.TestRunner.privateRun(TestRunner.java:767)
	at org.testng.TestRunner.run(TestRunner.java:617)
	at org.testng.SuiteRunner.runTest(SuiteRunner.java:334)
	at org.testng.SuiteRunner.runSequentially(SuiteRunner.java:329)
	at org.testng.SuiteRunner.privateRun(SuiteRunner.java:291)
	at org.testng.SuiteRunner.run(SuiteRunner.java:240)
	at org.testng.SuiteRunnerWorker.runSuite(SuiteRunnerWorker.java:52)
	at org.testng.SuiteRunnerWorker.run(SuiteRunnerWorker.java:86)
	at org.testng.TestNG.runSuitesSequentially(TestNG.java:1198)
	at org.testng.TestNG.runSuitesLocally(TestNG.java:1123)
	at org.testng.TestNG.run(TestNG.java:1031)
	at org.testng.remote.AbstractRemoteTestNG.run(AbstractRemoteTestNG.java:115)
	at org.testng.remote.RemoteTestNG.initAndRun(RemoteTestNG.java:251)
	at org.testng.remote.RemoteTestNG.main(RemoteTestNG.java:77)
Caused by: org.testng.TestException: 
Method InvocationCountTest.math()[pri:0, instance:net.groot.data.InvocationCountTest@3701eaf6] should have thrown an exception of class java.lang.NumberFormatException
	at org.testng.internal.Invoker.handleInvocationResults(Invoker.java:1512)
	at org.testng.internal.Invoker.invokeMethod(Invoker.java:754)
	at org.testng.internal.Invoker.invokeTestMethod(Invoker.java:901)
	at org.testng.internal.Invoker.invokeTestMethods(Invoker.java:1231)
	... 16 more
]]>
    </failure>
  </testcase> <!-- math -->
  <testcase name="math" time="0.001" classname="net.groot.data.InvocationCountTest">
    <failure type="org.testng.TestException" message="
Expected exception java.lang.NumberFormatException but got org.testng.TestException: 
Method InvocationCountTest.math()[pri:0, instance:net.groot.data.InvocationCountTest@3701eaf6] should have thrown an exception of class java.lang.NumberFormatException">
      <![CDATA[org.testng.TestException: 
Expected exception java.lang.NumberFormatException but got org.testng.TestException: 
Method InvocationCountTest.math()[pri:0, instance:net.groot.data.InvocationCountTest@3701eaf6] should have thrown an exception of class java.lang.NumberFormatException
	at org.testng.internal.Invoker.handleInvocationResults(Invoker.java:1497)
	at org.testng.internal.Invoker.invokeTestMethods(Invoker.java:1245)
	at org.testng.internal.TestMethodWorker.invokeTestMethods(TestMethodWorker.java:127)
	at org.testng.internal.TestMethodWorker.run(TestMethodWorker.java:111)
	at org.testng.TestRunner.privateRun(TestRunner.java:767)
	at org.testng.TestRunner.run(TestRunner.java:617)
	at org.testng.SuiteRunner.runTest(SuiteRunner.java:334)
	at org.testng.SuiteRunner.runSequentially(SuiteRunner.java:329)
	at org.testng.SuiteRunner.privateRun(SuiteRunner.java:291)
	at org.testng.SuiteRunner.run(SuiteRunner.java:240)
	at org.testng.SuiteRunnerWorker.runSuite(SuiteRunnerWorker.java:52)
	at org.testng.SuiteRunnerWorker.run(SuiteRunnerWorker.java:86)
	at org.testng.TestNG.runSuitesSequentially(TestNG.java:1198)
	at org.testng.TestNG.runSuitesLocally(TestNG.java:1123)
	at org.testng.TestNG.run(TestNG.java:1031)
	at org.testng.remote.AbstractRemoteTestNG.run(AbstractRemoteTestNG.java:115)
	at org.testng.remote.RemoteTestNG.initAndRun(RemoteTestNG.java:251)
	at org.testng.remote.RemoteTestNG.main(RemoteTestNG.java:77)
Caused by: org.testng.TestException: 
Method InvocationCountTest.math()[pri:0, instance:net.groot.data.InvocationCountTest@3701eaf6] should have thrown an exception of class java.lang.NumberFormatException
	at org.testng.internal.Invoker.handleInvocationResults(Invoker.java:1512)
	at org.testng.internal.Invoker.invokeMethod(Invoker.java:754)
	at org.testng.internal.Invoker.invokeTestMethod(Invoker.java:901)
	at org.testng.internal.Invoker.invokeTestMethods(Invoker.java:1231)
	... 16 more
]]>
    </failure>
  </testcase> <!-- math -->
  <testcase name="invokeProvider" time="0.005" classname="net.groot.data.InvocationCountTest"/>
  <testcase name="invokeProvider" time="0.003" classname="net.groot.data.InvocationCountTest"/>
  <testcase name="math" time="0.011" classname="net.groot.data.InvocationCountTest">
    <failure type="org.testng.TestException" message="
Expected exception java.lang.NumberFormatException but got org.testng.TestException: 
Method InvocationCountTest.math()[pri:0, instance:net.groot.data.InvocationCountTest@3701eaf6] should have thrown an exception of class java.lang.NumberFormatException">
      <![CDATA[org.testng.TestException: 
Expected exception java.lang.NumberFormatException but got org.testng.TestException: 
Method InvocationCountTest.math()[pri:0, instance:net.groot.data.InvocationCountTest@3701eaf6] should have thrown an exception of class java.lang.NumberFormatException
	at org.testng.internal.Invoker.handleInvocationResults(Invoker.java:1497)
	at org.testng.internal.Invoker.invokeTestMethods(Invoker.java:1245)
	at org.testng.internal.TestMethodWorker.invokeTestMethods(TestMethodWorker.java:127)
	at org.testng.internal.TestMethodWorker.run(TestMethodWorker.java:111)
	at org.testng.TestRunner.privateRun(TestRunner.java:767)
	at org.testng.TestRunner.run(TestRunner.java:617)
	at org.testng.SuiteRunner.runTest(SuiteRunner.java:334)
	at org.testng.SuiteRunner.runSequentially(SuiteRunner.java:329)
	at org.testng.SuiteRunner.privateRun(SuiteRunner.java:291)
	at org.testng.SuiteRunner.run(SuiteRunner.java:240)
	at org.testng.SuiteRunnerWorker.runSuite(SuiteRunnerWorker.java:52)
	at org.testng.SuiteRunnerWorker.run(SuiteRunnerWorker.java:86)
	at org.testng.TestNG.runSuitesSequentially(TestNG.java:1198)
	at org.testng.TestNG.runSuitesLocally(TestNG.java:1123)
	at org.testng.TestNG.run(TestNG.java:1031)
	at org.testng.remote.AbstractRemoteTestNG.run(AbstractRemoteTestNG.java:115)
	at org.testng.remote.RemoteTestNG.initAndRun(RemoteTestNG.java:251)
	at org.testng.remote.RemoteTestNG.main(RemoteTestNG.java:77)
Caused by: org.testng.TestException: 
Method InvocationCountTest.math()[pri:0, instance:net.groot.data.InvocationCountTest@3701eaf6] should have thrown an exception of class java.lang.NumberFormatException
	at org.testng.internal.Invoker.handleInvocationResults(Invoker.java:1512)
	at org.testng.internal.Invoker.invokeMethod(Invoker.java:754)
	at org.testng.internal.Invoker.invokeTestMethod(Invoker.java:901)
	at org.testng.internal.Invoker.invokeTestMethods(Invoker.java:1231)
	... 16 more
]]>
    </failure>
  </testcase> <!-- math -->
  <testcase name="math" time="0.006" classname="net.groot.data.InvocationCountTest">
    <failure type="org.testng.TestException" message="
Expected exception java.lang.NumberFormatException but got org.testng.TestException: 
Method InvocationCountTest.math()[pri:0, instance:net.groot.data.InvocationCountTest@3701eaf6] should have thrown an exception of class java.lang.NumberFormatException">
      <![CDATA[org.testng.TestException: 
Expected exception java.lang.NumberFormatException but got org.testng.TestException: 
Method InvocationCountTest.math()[pri:0, instance:net.groot.data.InvocationCountTest@3701eaf6] should have thrown an exception of class java.lang.NumberFormatException
	at org.testng.internal.Invoker.handleInvocationResults(Invoker.java:1497)
	at org.testng.internal.Invoker.invokeTestMethods(Invoker.java:1245)
	at org.testng.internal.TestMethodWorker.invokeTestMethods(TestMethodWorker.java:127)
	at org.testng.internal.TestMethodWorker.run(TestMethodWorker.java:111)
	at org.testng.TestRunner.privateRun(TestRunner.java:767)
	at org.testng.TestRunner.run(TestRunner.java:617)
	at org.testng.SuiteRunner.runTest(SuiteRunner.java:334)
	at org.testng.SuiteRunner.runSequentially(SuiteRunner.java:329)
	at org.testng.SuiteRunner.privateRun(SuiteRunner.java:291)
	at org.testng.SuiteRunner.run(SuiteRunner.java:240)
	at org.testng.SuiteRunnerWorker.runSuite(SuiteRunnerWorker.java:52)
	at org.testng.SuiteRunnerWorker.run(SuiteRunnerWorker.java:86)
	at org.testng.TestNG.runSuitesSequentially(TestNG.java:1198)
	at org.testng.TestNG.runSuitesLocally(TestNG.java:1123)
	at org.testng.TestNG.run(TestNG.java:1031)
	at org.testng.remote.AbstractRemoteTestNG.run(AbstractRemoteTestNG.java:115)
	at org.testng.remote.RemoteTestNG.initAndRun(RemoteTestNG.java:251)
	at org.testng.remote.RemoteTestNG.main(RemoteTestNG.java:77)
Caused by: org.testng.TestException: 
Method InvocationCountTest.math()[pri:0, instance:net.groot.data.InvocationCountTest@3701eaf6] should have thrown an exception of class java.lang.NumberFormatException
	at org.testng.internal.Invoker.handleInvocationResults(Invoker.java:1512)
	at org.testng.internal.Invoker.invokeMethod(Invoker.java:754)
	at org.testng.internal.Invoker.invokeTestMethod(Invoker.java:901)
	at org.testng.internal.Invoker.invokeTestMethods(Invoker.java:1231)
	... 16 more
]]>
    </failure>
  </testcase> <!-- math -->
  <testcase name="invokeProvider" time="0.003" classname="net.groot.data.InvocationCountTest"/>
  <testcase name="mathError" time="0.001" classname="net.groot.data.InvocationCountTest"/>
  <testcase name="invokeProvider" time="0.003" classname="net.groot.data.InvocationCountTest"/>
  <testcase name="mathError" time="0.006" classname="net.groot.data.InvocationCountTest"/>
  <testcase name="math" time="0.002" classname="net.groot.data.InvocationCountTest">
    <failure type="org.testng.TestException" message="
Expected exception java.lang.NumberFormatException but got org.testng.TestException: 
Method InvocationCountTest.math()[pri:0, instance:net.groot.data.InvocationCountTest@3701eaf6] should have thrown an exception of class java.lang.NumberFormatException">
      <![CDATA[org.testng.TestException: 
Expected exception java.lang.NumberFormatException but got org.testng.TestException: 
Method InvocationCountTest.math()[pri:0, instance:net.groot.data.InvocationCountTest@3701eaf6] should have thrown an exception of class java.lang.NumberFormatException
	at org.testng.internal.Invoker.handleInvocationResults(Invoker.java:1497)
	at org.testng.internal.Invoker.invokeTestMethods(Invoker.java:1245)
	at org.testng.internal.TestMethodWorker.invokeTestMethods(TestMethodWorker.java:127)
	at org.testng.internal.TestMethodWorker.run(TestMethodWorker.java:111)
	at org.testng.TestRunner.privateRun(TestRunner.java:767)
	at org.testng.TestRunner.run(TestRunner.java:617)
	at org.testng.SuiteRunner.runTest(SuiteRunner.java:334)
	at org.testng.SuiteRunner.runSequentially(SuiteRunner.java:329)
	at org.testng.SuiteRunner.privateRun(SuiteRunner.java:291)
	at org.testng.SuiteRunner.run(SuiteRunner.java:240)
	at org.testng.SuiteRunnerWorker.runSuite(SuiteRunnerWorker.java:52)
	at org.testng.SuiteRunnerWorker.run(SuiteRunnerWorker.java:86)
	at org.testng.TestNG.runSuitesSequentially(TestNG.java:1198)
	at org.testng.TestNG.runSuitesLocally(TestNG.java:1123)
	at org.testng.TestNG.run(TestNG.java:1031)
	at org.testng.remote.AbstractRemoteTestNG.run(AbstractRemoteTestNG.java:115)
	at org.testng.remote.RemoteTestNG.initAndRun(RemoteTestNG.java:251)
	at org.testng.remote.RemoteTestNG.main(RemoteTestNG.java:77)
Caused by: org.testng.TestException: 
Method InvocationCountTest.math()[pri:0, instance:net.groot.data.InvocationCountTest@3701eaf6] should have thrown an exception of class java.lang.NumberFormatException
	at org.testng.internal.Invoker.handleInvocationResults(Invoker.java:1512)
	at org.testng.internal.Invoker.invokeMethod(Invoker.java:754)
	at org.testng.internal.Invoker.invokeTestMethod(Invoker.java:901)
	at org.testng.internal.Invoker.invokeTestMethods(Invoker.java:1231)
	... 16 more
]]>
    </failure>
  </testcase> <!-- math -->
  <testcase name="mathError" time="0.002" classname="net.groot.data.InvocationCountTest"/>
  <testcase name="mathError" time="0.001" classname="net.groot.data.InvocationCountTest"/>
  <testcase name="mathError" time="0.001" classname="net.groot.data.InvocationCountTest"/>
  <testcase name="math" time="0.012" classname="net.groot.data.InvocationCountTest">
    <failure type="org.testng.TestException" message="
Expected exception java.lang.NumberFormatException but got org.testng.TestException: 
Method InvocationCountTest.math()[pri:0, instance:net.groot.data.InvocationCountTest@3701eaf6] should have thrown an exception of class java.lang.NumberFormatException">
      <![CDATA[org.testng.TestException: 
Expected exception java.lang.NumberFormatException but got org.testng.TestException: 
Method InvocationCountTest.math()[pri:0, instance:net.groot.data.InvocationCountTest@3701eaf6] should have thrown an exception of class java.lang.NumberFormatException
	at org.testng.internal.Invoker.handleInvocationResults(Invoker.java:1497)
	at org.testng.internal.Invoker.invokeTestMethods(Invoker.java:1245)
	at org.testng.internal.TestMethodWorker.invokeTestMethods(TestMethodWorker.java:127)
	at org.testng.internal.TestMethodWorker.run(TestMethodWorker.java:111)
	at org.testng.TestRunner.privateRun(TestRunner.java:767)
	at org.testng.TestRunner.run(TestRunner.java:617)
	at org.testng.SuiteRunner.runTest(SuiteRunner.java:334)
	at org.testng.SuiteRunner.runSequentially(SuiteRunner.java:329)
	at org.testng.SuiteRunner.privateRun(SuiteRunner.java:291)
	at org.testng.SuiteRunner.run(SuiteRunner.java:240)
	at org.testng.SuiteRunnerWorker.runSuite(SuiteRunnerWorker.java:52)
	at org.testng.SuiteRunnerWorker.run(SuiteRunnerWorker.java:86)
	at org.testng.TestNG.runSuitesSequentially(TestNG.java:1198)
	at org.testng.TestNG.runSuitesLocally(TestNG.java:1123)
	at org.testng.TestNG.run(TestNG.java:1031)
	at org.testng.remote.AbstractRemoteTestNG.run(AbstractRemoteTestNG.java:115)
	at org.testng.remote.RemoteTestNG.initAndRun(RemoteTestNG.java:251)
	at org.testng.remote.RemoteTestNG.main(RemoteTestNG.java:77)
Caused by: org.testng.TestException: 
Method InvocationCountTest.math()[pri:0, instance:net.groot.data.InvocationCountTest@3701eaf6] should have thrown an exception of class java.lang.NumberFormatException
	at org.testng.internal.Invoker.handleInvocationResults(Invoker.java:1512)
	at org.testng.internal.Invoker.invokeMethod(Invoker.java:754)
	at org.testng.internal.Invoker.invokeTestMethod(Invoker.java:901)
	at org.testng.internal.Invoker.invokeTestMethods(Invoker.java:1231)
	... 16 more
]]>
    </failure>
  </testcase> <!-- math -->
  <testcase name="invokeProvider" time="0.002" classname="net.groot.data.InvocationCountTest"/>
  <testcase name="invokeProvider" time="0.003" classname="net.groot.data.InvocationCountTest"/>
  <testcase name="invokeProvider" time="0.003" classname="net.groot.data.InvocationCountTest"/>
  <testcase name="math" time="0.002" classname="net.groot.data.InvocationCountTest">
    <failure type="org.testng.TestException" message="
Expected exception java.lang.NumberFormatException but got org.testng.TestException: 
Method InvocationCountTest.math()[pri:0, instance:net.groot.data.InvocationCountTest@3701eaf6] should have thrown an exception of class java.lang.NumberFormatException">
      <![CDATA[org.testng.TestException: 
Expected exception java.lang.NumberFormatException but got org.testng.TestException: 
Method InvocationCountTest.math()[pri:0, instance:net.groot.data.InvocationCountTest@3701eaf6] should have thrown an exception of class java.lang.NumberFormatException
	at org.testng.internal.Invoker.handleInvocationResults(Invoker.java:1497)
	at org.testng.internal.Invoker.invokeTestMethods(Invoker.java:1245)
	at org.testng.internal.TestMethodWorker.invokeTestMethods(TestMethodWorker.java:127)
	at org.testng.internal.TestMethodWorker.run(TestMethodWorker.java:111)
	at org.testng.TestRunner.privateRun(TestRunner.java:767)
	at org.testng.TestRunner.run(TestRunner.java:617)
	at org.testng.SuiteRunner.runTest(SuiteRunner.java:334)
	at org.testng.SuiteRunner.runSequentially(SuiteRunner.java:329)
	at org.testng.SuiteRunner.privateRun(SuiteRunner.java:291)
	at org.testng.SuiteRunner.run(SuiteRunner.java:240)
	at org.testng.SuiteRunnerWorker.runSuite(SuiteRunnerWorker.java:52)
	at org.testng.SuiteRunnerWorker.run(SuiteRunnerWorker.java:86)
	at org.testng.TestNG.runSuitesSequentially(TestNG.java:1198)
	at org.testng.TestNG.runSuitesLocally(TestNG.java:1123)
	at org.testng.TestNG.run(TestNG.java:1031)
	at org.testng.remote.AbstractRemoteTestNG.run(AbstractRemoteTestNG.java:115)
	at org.testng.remote.RemoteTestNG.initAndRun(RemoteTestNG.java:251)
	at org.testng.remote.RemoteTestNG.main(RemoteTestNG.java:77)
Caused by: org.testng.TestException: 
Method InvocationCountTest.math()[pri:0, instance:net.groot.data.InvocationCountTest@3701eaf6] should have thrown an exception of class java.lang.NumberFormatException
	at org.testng.internal.Invoker.handleInvocationResults(Invoker.java:1512)
	at org.testng.internal.Invoker.invokeMethod(Invoker.java:754)
	at org.testng.internal.Invoker.invokeTestMethod(Invoker.java:901)
	at org.testng.internal.Invoker.invokeTestMethods(Invoker.java:1231)
	... 16 more
]]>
    </failure>
  </testcase> <!-- math -->
  <testcase name="invokeProvider" time="0.001" classname="net.groot.data.InvocationCountTest"/>
  <testcase name="math" time="0.003" classname="net.groot.data.InvocationCountTest">
    <failure type="org.testng.TestException" message="
Expected exception java.lang.NumberFormatException but got org.testng.TestException: 
Method InvocationCountTest.math()[pri:0, instance:net.groot.data.InvocationCountTest@3701eaf6] should have thrown an exception of class java.lang.NumberFormatException">
      <![CDATA[org.testng.TestException: 
Expected exception java.lang.NumberFormatException but got org.testng.TestException: 
Method InvocationCountTest.math()[pri:0, instance:net.groot.data.InvocationCountTest@3701eaf6] should have thrown an exception of class java.lang.NumberFormatException
	at org.testng.internal.Invoker.handleInvocationResults(Invoker.java:1497)
	at org.testng.internal.Invoker.invokeTestMethods(Invoker.java:1245)
	at org.testng.internal.TestMethodWorker.invokeTestMethods(TestMethodWorker.java:127)
	at org.testng.internal.TestMethodWorker.run(TestMethodWorker.java:111)
	at org.testng.TestRunner.privateRun(TestRunner.java:767)
	at org.testng.TestRunner.run(TestRunner.java:617)
	at org.testng.SuiteRunner.runTest(SuiteRunner.java:334)
	at org.testng.SuiteRunner.runSequentially(SuiteRunner.java:329)
	at org.testng.SuiteRunner.privateRun(SuiteRunner.java:291)
	at org.testng.SuiteRunner.run(SuiteRunner.java:240)
	at org.testng.SuiteRunnerWorker.runSuite(SuiteRunnerWorker.java:52)
	at org.testng.SuiteRunnerWorker.run(SuiteRunnerWorker.java:86)
	at org.testng.TestNG.runSuitesSequentially(TestNG.java:1198)
	at org.testng.TestNG.runSuitesLocally(TestNG.java:1123)
	at org.testng.TestNG.run(TestNG.java:1031)
	at org.testng.remote.AbstractRemoteTestNG.run(AbstractRemoteTestNG.java:115)
	at org.testng.remote.RemoteTestNG.initAndRun(RemoteTestNG.java:251)
	at org.testng.remote.RemoteTestNG.main(RemoteTestNG.java:77)
Caused by: org.testng.TestException: 
Method InvocationCountTest.math()[pri:0, instance:net.groot.data.InvocationCountTest@3701eaf6] should have thrown an exception of class java.lang.NumberFormatException
	at org.testng.internal.Invoker.handleInvocationResults(Invoker.java:1512)
	at org.testng.internal.Invoker.invokeMethod(Invoker.java:754)
	at org.testng.internal.Invoker.invokeTestMethod(Invoker.java:901)
	at org.testng.internal.Invoker.invokeTestMethods(Invoker.java:1231)
	... 16 more
]]>
    </failure>
  </testcase> <!-- math -->
  <testcase name="invokeProvider" time="0.005" classname="net.groot.data.InvocationCountTest"/>
  <testcase name="mathError" time="0.000" classname="net.groot.data.InvocationCountTest"/>
  <testcase name="math" time="0.001" classname="net.groot.data.InvocationCountTest">
    <failure type="org.testng.TestException" message="
Expected exception java.lang.NumberFormatException but got org.testng.TestException: 
Method InvocationCountTest.math()[pri:0, instance:net.groot.data.InvocationCountTest@3701eaf6] should have thrown an exception of class java.lang.NumberFormatException">
      <![CDATA[org.testng.TestException: 
Expected exception java.lang.NumberFormatException but got org.testng.TestException: 
Method InvocationCountTest.math()[pri:0, instance:net.groot.data.InvocationCountTest@3701eaf6] should have thrown an exception of class java.lang.NumberFormatException
	at org.testng.internal.Invoker.handleInvocationResults(Invoker.java:1497)
	at org.testng.internal.Invoker.invokeTestMethods(Invoker.java:1245)
	at org.testng.internal.TestMethodWorker.invokeTestMethods(TestMethodWorker.java:127)
	at org.testng.internal.TestMethodWorker.run(TestMethodWorker.java:111)
	at org.testng.TestRunner.privateRun(TestRunner.java:767)
	at org.testng.TestRunner.run(TestRunner.java:617)
	at org.testng.SuiteRunner.runTest(SuiteRunner.java:334)
	at org.testng.SuiteRunner.runSequentially(SuiteRunner.java:329)
	at org.testng.SuiteRunner.privateRun(SuiteRunner.java:291)
	at org.testng.SuiteRunner.run(SuiteRunner.java:240)
	at org.testng.SuiteRunnerWorker.runSuite(SuiteRunnerWorker.java:52)
	at org.testng.SuiteRunnerWorker.run(SuiteRunnerWorker.java:86)
	at org.testng.TestNG.runSuitesSequentially(TestNG.java:1198)
	at org.testng.TestNG.runSuitesLocally(TestNG.java:1123)
	at org.testng.TestNG.run(TestNG.java:1031)
	at org.testng.remote.AbstractRemoteTestNG.run(AbstractRemoteTestNG.java:115)
	at org.testng.remote.RemoteTestNG.initAndRun(RemoteTestNG.java:251)
	at org.testng.remote.RemoteTestNG.main(RemoteTestNG.java:77)
Caused by: org.testng.TestException: 
Method InvocationCountTest.math()[pri:0, instance:net.groot.data.InvocationCountTest@3701eaf6] should have thrown an exception of class java.lang.NumberFormatException
	at org.testng.internal.Invoker.handleInvocationResults(Invoker.java:1512)
	at org.testng.internal.Invoker.invokeMethod(Invoker.java:754)
	at org.testng.internal.Invoker.invokeTestMethod(Invoker.java:901)
	at org.testng.internal.Invoker.invokeTestMethods(Invoker.java:1231)
	... 16 more
]]>
    </failure>
  </testcase> <!-- math -->
  <testcase name="invokeProvider" time="0.001" classname="net.groot.data.InvocationCountTest"/>
  <testcase name="invokeProvider" time="0.004" classname="net.groot.data.InvocationCountTest"/>
  <testcase name="invokeProvider" time="0.007" classname="net.groot.data.InvocationCountTest"/>
  <testcase name="invokeProvider" time="0.001" classname="net.groot.data.InvocationCountTest"/>
  <testcase name="mathError" time="0.001" classname="net.groot.data.InvocationCountTest"/>
  <testcase name="invokeProvider" time="0.002" classname="net.groot.data.InvocationCountTest"/>
</testsuite> <!-- net.groot.data.InvocationCountTest -->
